<?xml version='1.0' encoding='utf-8'?>
<robot name="astra">
    <link name="Spine">
        <inertial>
            <origin xyz="0.02769385984751416 -0.006697646524053425 0.03140014675274089" rpy="0.0 -0.0 0.0" />
            <mass value="0.2716788388343432" />
            <inertia ixx="0.00028813863899506006" iyy="0.0004435432371230341" izz="0.0006822424384377752" ixy="-1.1374085606633954e-06" iyz="1.6776739416090396e-06" ixz="-4.969926318824534e-05" />
        </inertial>
        <visual name="Spine_visual">
            <origin xyz="-0.2765000021051775 -0.006999947933427104 2.6686708084727728e-05" rpy="1.5707963267940581 0.007625102576444858 1.5707963267948946" />
            <geometry>
                <mesh filename="meshes/Spine.stl" scale="0.001 0.001 0.001" />
            </geometry>
        </visual>
        <collision name="Spine_collision">
            <origin xyz="-0.2765000021051775 -0.006999947933427104 2.6686708084727728e-05" rpy="1.5707963267940581 0.007625102576444858 1.5707963267948946" />
            <geometry>
                <mesh filename="meshes/Spine.stl" scale="0.001 0.001 0.001" />
            </geometry>
        </collision>
    </link>
    <link name="FR_tibia">
        <inertial>
            <origin xyz="-0.05148378979881365 -0.01699950807685667 0.00012936828483873342" rpy="0.0 -0.0 0.0" />
            <mass value="0.06643041309117052" />
            <inertia ixx="7.3241854965152425e-06" iyy="0.00017282619397882178" izz="0.00016950471436330983" ixy="-1.0920844415419499e-11" iyz="-2.3886775781754105e-08" ixz="-1.4321870343302173e-09" />
        </inertial>
        <visual name="FR_tibia_visual">
            <origin xyz="-0.12650000210517606 0.11487056547626065 0.24488122968499196" rpy="-1.5707963267957352 -0.007625102576446537 -1.5707963267948946" />
            <geometry>
                <mesh filename="meshes/FR_tibia.stl" scale="0.001 0.001 0.001" />
            </geometry>
        </visual>
        <collision name="FR_tibia_collision">
            <origin xyz="-0.12650000210517606 0.11487056547626065 0.24488122968499196" rpy="-1.5707963267957352 -0.007625102576446537 -1.5707963267948946" />
            <geometry>
                <mesh filename="meshes/FR_tibia.stl" scale="0.001 0.001 0.001" />
            </geometry>
        </collision>
    </link>
    <link name="FR_femur">
        <inertial>
            <origin xyz="-0.009632030109484048 0.04662072068236703 -0.001018747807288385" rpy="-1.9721522630525295e-31 -0.0 0.0" />
            <mass value="0.5478239660925192" />
            <inertia ixx="0.00038983662569730404" iyy="0.0009198142691163179" izz="0.00095056365284809" ixy="0.00012718937153704052" iyz="-1.0135726810300818e-05" ixz="2.5436776278709038e-06" />
        </inertial>
        <visual name="FR_femur_visual">
            <origin xyz="-0.2665000021051761 -0.05787222547626062 -0.24531584968499195" rpy="1.5707963267940581 0.007625102576446425 1.5707963267948946" />
            <geometry>
                <mesh filename="meshes/FR_femur.stl" scale="0.001 0.001 0.001" />
            </geometry>
        </visual>
        <collision name="FR_femur_collision">
            <origin xyz="-0.2665000021051761 -0.05787222547626062 -0.24531584968499195" rpy="1.5707963267940581 0.007625102576446425 1.5707963267948946" />
            <geometry>
                <mesh filename="meshes/FR_femur.stl" scale="0.001 0.001 0.001" />
            </geometry>
        </collision>
    </link>
    <link name="FR_hip">
        <inertial>
            <origin xyz="0.05152677276375954 -6.812267368466962e-05 -0.02832992195958169" rpy="0.0 -1.7598217861546274e-46 0.0" />
            <mass value="0.4276561259852312" />
            <inertia ixx="0.0002238777317536758" iyy="0.0003062069058394311" izz="0.0003823631243674157" ixy="2.129288805586995e-07" iyz="-5.588930044728158e-07" ixz="2.4434049486920164e-05" />
        </inertial>
        <visual name="FR_hip_visual">
            <origin xyz="-0.18721078968548568 -0.26650000210887714 -0.07142956547639677" rpy="1.5707963267949439 -1.5631712242184466 3.1415926535895866" />
            <geometry>
                <mesh filename="meshes/FR_hip.stl" scale="0.001 0.001 0.001" />
            </geometry>
        </visual>
        <collision name="FR_hip_collision">
            <origin xyz="-0.18721078968548568 -0.26650000210887714 -0.07142956547639677" rpy="1.5707963267949439 -1.5631712242184466 3.1415926535895866" />
            <geometry>
                <mesh filename="meshes/FR_hip.stl" scale="0.001 0.001 0.001" />
            </geometry>
        </collision>
    </link>
    <link name="FL_tibia">
        <inertial>
            <origin xyz="-0.05148378980268236 -0.016999507429937194 0.0001293705355556085" rpy="0.0 -0.0 0.0" />
            <mass value="0.06643041309117047" />
            <inertia ixx="7.324185496590703e-06" iyy="0.0001728261939788955" izz="0.00016950471436334453" ixy="-1.0920903179173094e-11" iyz="-2.3886775780877108e-08" ixz="-1.432187415537508e-09" />
        </inertial>
        <visual name="FL_tibia_visual">
            <origin xyz="-0.12650000210517603 0.11112286452374004 -0.24660447968499197" rpy="1.5707963267940581 0.007625102576443637 1.5707963267948946" />
            <geometry>
                <mesh filename="meshes/FL_tibia.stl" scale="0.001 0.001 0.001" />
            </geometry>
        </visual>
        <collision name="FL_tibia_collision">
            <origin xyz="-0.12650000210517603 0.11112286452374004 -0.24660447968499197" rpy="1.5707963267940581 0.007625102576443637 1.5707963267948946" />
            <geometry>
                <mesh filename="meshes/FL_tibia.stl" scale="0.001 0.001 0.001" />
            </geometry>
        </collision>
    </link>
    <link name="FL_femur">
        <inertial>
            <origin xyz="-0.009525673473169113 0.04663083445845105 0.00030768809464063905" rpy="1.9721522630525295e-31 -0.0 0.0" />
            <mass value="0.54782396609252" />
            <inertia ixx="0.00038983662569448685" iyy="0.0009212467337586243" izz="0.0009513636241155758" ixy="0.00012859805913639086" iyz="1.0599874377095021e-05" ixz="-4.4279953090515305e-06" />
        </inertial>
        <visual name="FL_femur_visual">
            <origin xyz="-0.26650000210517605 -0.05412452452374012 0.246169859684992" rpy="-1.5707963267957352 -0.007625102576443339 -1.5707963267948946" />
            <geometry>
                <mesh filename="meshes/FL_femur.stl" scale="0.001 0.001 0.001" />
            </geometry>
        </visual>
        <collision name="FL_femur_collision">
            <origin xyz="-0.26650000210517605 -0.05412452452374012 0.246169859684992" rpy="-1.5707963267957352 -0.007625102576443339 -1.5707963267948946" />
            <geometry>
                <mesh filename="meshes/FL_femur.stl" scale="0.001 0.001 0.001" />
            </geometry>
        </collision>
    </link>
    <link name="FL_hip">
        <inertial>
            <origin xyz="0.05108876478156873 6.81191361698552e-05 0.02911238840901846" rpy="0.0 -1.7598217861546274e-46 0.0" />
            <mass value="0.4276561259852311" />
            <inertia ixx="0.00022465972063374917" iyy="0.00030620690583941373" izz="0.0003815811354755535" ixy="-2.0437091610355143e-07" iyz="-5.620767966883576e-07" ixz="-2.6839245207135573e-05" />
        </inertial>
        <visual name="FL_hip_visual">
            <origin xyz="-0.1882782896854858 -0.2665000021088764 0.06856636452360315" rpy="1.570796326794942 -1.5631712242184466 3.1415926535895866" />
            <geometry>
                <mesh filename="meshes/FL_hip.stl" scale="0.001 0.001 0.001" />
            </geometry>
        </visual>
        <collision name="FL_hip_collision">
            <origin xyz="-0.1882782896854858 -0.2665000021088764 0.06856636452360315" rpy="1.570796326794942 -1.5631712242184466 3.1415926535895866" />
            <geometry>
                <mesh filename="meshes/FL_hip.stl" scale="0.001 0.001 0.001" />
            </geometry>
        </collision>
    </link>
    <link name="RR_tibia">
        <inertial>
            <origin xyz="-0.05148378938247298 -0.01699987372410975 6.455377009196184e-05" rpy="-1.9721522630525295e-31 -0.0 0.0" />
            <mass value="0.06643041309117047" />
            <inertia ixx="7.324185496501365e-06" iyy="0.000172826327836868" izz="0.00016950458050522859" ixy="-5.460494578201795e-12" iyz="-1.1222892580972054e-08" ixz="-1.432218403553481e-09" />
        </inertial>
        <visual name="RR_tibia_visual">
            <origin xyz="-0.12600000210517748 0.11210704793323065 -0.23442911670881217" rpy="-1.5707963267948877 -0.0038125512531824745 -1.5707963267948946" />
            <geometry>
                <mesh filename="meshes/RR_tibia.stl" scale="0.001 0.001 0.001" />
            </geometry>
        </visual>
        <collision name="RR_tibia_collision">
            <origin xyz="-0.12600000210517748 0.11210704793323065 -0.23442911670881217" rpy="-1.5707963267948877 -0.0038125512531824745 -1.5707963267948946" />
            <geometry>
                <mesh filename="meshes/RR_tibia.stl" scale="0.001 0.001 0.001" />
            </geometry>
        </collision>
    </link>
    <link name="RR_femur">
        <inertial>
            <origin xyz="-0.009525673053035071 0.04662932633818336 0.00048546063817536125" rpy="1.9721522630525295e-31 -0.0 0.0" />
            <mass value="0.5478239660925199" />
            <inertia ixx="0.0003898366261738048" iyy="0.0009211663476761394" izz="0.0009514440107178256" ixy="0.00012861400643020968" iyz="1.0484745251910334e-05" ixz="-3.937677349824315e-06" />
        </inertial>
        <visual name="RR_femur_visual">
            <origin xyz="-0.2660000021051775 -0.05510745793323071 0.23421179670881226" rpy="1.5707963267949057 0.003812551253182178 1.5707963267948946" />
            <geometry>
                <mesh filename="meshes/RR_femur.stl" scale="0.001 0.001 0.001" />
            </geometry>
        </visual>
        <collision name="RR_femur_collision">
            <origin xyz="-0.2660000021051775 -0.05510745793323071 0.23421179670881226" rpy="1.5707963267949057 0.003812551253182178 1.5707963267948946" />
            <geometry>
                <mesh filename="meshes/RR_femur.stl" scale="0.001 0.001 0.001" />
            </geometry>
        </collision>
    </link>
    <link name="RR_hip">
        <inertial>
            <origin xyz="0.05119938415783576 -6.811914863366297e-05 -0.028917404603797152" rpy="0.0 -1.9914417216547702e-43 0.0" />
            <mass value="0.42765614096569765" />
            <inertia ixx="0.00022445736633032952" iyy="0.0003062069227032921" izz="0.00038178352227940615" ixy="2.065100330026226e-07" iyz="-5.612900104959906e-07" ixz="2.624020499396785e-05" />
        </inertial>
        <visual name="RR_hip_visual">
            <origin xyz="-0.17626559670936304 0.2660000021006799 -0.06932848792833637" rpy="1.570796326796866 -1.566983775538314 -6.017748589733377e-13" />
            <geometry>
                <mesh filename="meshes/RR_hip.stl" scale="0.001 0.001 0.001" />
            </geometry>
        </visual>
        <collision name="RR_hip_collision">
            <origin xyz="-0.17626559670936304 0.2660000021006799 -0.06932848792833637" rpy="1.570796326796866 -1.566983775538314 -6.017748589733377e-13" />
            <geometry>
                <mesh filename="meshes/RR_hip.stl" scale="0.001 0.001 0.001" />
            </geometry>
        </collision>
    </link>
    <link name="RL_tibia">
        <inertial>
            <origin xyz="-0.05148379137860532 -0.016999878634483975 6.455850487306236e-05" rpy="-1.9721522630525295e-31 -0.0 0.0" />
            <mass value="0.06643041309117051" />
            <inertia ixx="7.324185496485752e-06" iyy="0.00017282632783685066" izz="0.00016950458050517047" ixy="-5.460546511489653e-12" iyz="-1.122289258141454e-08" ixz="-1.4322184996119867e-09" />
        </inertial>
        <visual name="RL_tibia_visual">
            <origin xyz="-0.12600000210517753 0.11389131206676995 0.23356748670881217" rpy="1.5707963267949057 0.003812551253185125 1.5707963267948946" />
            <geometry>
                <mesh filename="meshes/RL_tibia.stl" scale="0.001 0.001 0.001" />
            </geometry>
        </visual>
        <collision name="RL_tibia_collision">
            <origin xyz="-0.12600000210517753 0.11389131206676995 0.23356748670881217" rpy="1.5707963267949057 0.003812551253185125 1.5707963267948946" />
            <geometry>
                <mesh filename="meshes/RL_tibia.stl" scale="0.001 0.001 0.001" />
            </geometry>
        </collision>
    </link>
    <link name="RL_femur">
        <inertial>
            <origin xyz="-0.00963203168935646 0.04662426400033632 -0.0008410011746263635" rpy="1.9721522630525295e-31 -0.0 0.0" />
            <mass value="0.5478239660925199" />
            <inertia ixx="0.0003898366261703909" iyy="0.0009198920017766126" izz="0.0009504859207040074" ixy="0.00012717874927199726" iyz="-1.0252664727119344e-05" ixz="3.028573708353569e-06" />
        </inertial>
        <visual name="RL_femur_visual">
            <origin xyz="-0.2660000021051775 -0.05689173206676993 -0.23378479670881228" rpy="-1.5707963267948877 -0.0038125512531850146 -1.5707963267948946" />
            <geometry>
                <mesh filename="meshes/RL_femur.stl" scale="0.001 0.001 0.001" />
            </geometry>
        </visual>
        <collision name="RL_femur_collision">
            <origin xyz="-0.2660000021051775 -0.05689173206676993 -0.23378479670881228" rpy="-1.5707963267948877 -0.0038125512531850146 -1.5707963267948946" />
            <geometry>
                <mesh filename="meshes/RL_femur.stl" scale="0.001 0.001 0.001" />
            </geometry>
        </collision>
    </link>
    <link name="RL_hip">
        <inertial>
            <origin xyz="0.05141838587026122 6.812382988069743e-05 0.028526167165902866" rpy="0.0 -1.9914417216547702e-43 0.0" />
            <mass value="0.42765614096569793" />
            <inertia ixx="0.00022406636045059828" iyy="0.00030620692270314984" izz="0.0003821745281705935" ixy="-2.107936425915314e-07" iyz="-5.59697237668181e-07" ixz="-2.5037572159495846e-05" />
        </inertial>
        <visual name="RL_hip_visual">
            <origin xyz="-0.17573184670841088 0.2660000021010266 0.07067050207165984" rpy="1.5707963267968643 -1.566983775538314 -6.017748589733384e-13" />
            <geometry>
                <mesh filename="meshes/RL_hip.stl" scale="0.001 0.001 0.001" />
            </geometry>
        </visual>
        <collision name="RL_hip_collision">
            <origin xyz="-0.17573184670841088 0.2660000021010266 0.07067050207165984" rpy="1.5707963267968643 -1.566983775538314 -6.017748589733384e-13" />
            <geometry>
                <mesh filename="meshes/RL_hip.stl" scale="0.001 0.001 0.001" />
            </geometry>
        </collision>
    </link>
    <link name="Frontpart">
        <inertial>
            <origin xyz="0.07482832178288953 -0.011819323695477594 -0.0009062014731250256" rpy="0.0 -0.0 0.0" />
            <mass value="2.6950744218640232" />
            <inertia ixx="0.013420879847097694" iyy="0.013191602036138658" izz="0.010735525665266032" ixy="0.00048748918514439354" iyz="2.047238312624655e-05" ixz="-3.135508446171307e-05" />
        </inertial>
        <visual name="Frontpart_visual">
            <origin xyz="-0.049498559685484694 0.27650000210517595 0.00037743547645737954" rpy="-1.5707963267947913 1.5631712242184463 -3.141592653589528" />
            <geometry>
                <mesh filename="meshes/Frontpart.stl" scale="0.001 0.001 0.001" />
            </geometry>
        </visual>
        <collision name="Frontpart_collision">
            <origin xyz="-0.049498559685484694 0.27650000210517595 0.00037743547645737954" rpy="-1.5707963267947913 1.5631712242184463 -3.141592653589528" />
            <geometry>
                <mesh filename="meshes/Frontpart.stl" scale="0.001 0.001 0.001" />
            </geometry>
        </collision>
    </link>
    <link name="Backpart">
        <inertial>
            <origin xyz="-0.10870601628045662 0.0002838663607903813 0.005666258406695306" rpy="0.0 -0.0 0.0" />
            <mass value="2.332620946077069" />
            <inertia ixx="0.011882500249382172" iyy="0.009075484807072126" izz="0.01216735450819308" ixy="-1.2916302380370707e-05" iyz="-4.196309802355309e-06" ixz="-1.0472215236756683e-05" />
        </inertial>
        <visual name="Backpart_visual">
            <origin xyz="-3.2911875974539486e-09 -2.0667696487564057e-09 -0.2835000021051775" rpy="-4.530171917137859e-15 -2.0539484545575828e-15 -1.5746088780480803" />
            <geometry>
                <mesh filename="meshes/Backpart.stl" scale="0.001 0.001 0.001" />
            </geometry>
        </visual>
        <collision name="Backpart_collision">
            <origin xyz="-3.2911875974539486e-09 -2.0667696487564057e-09 -0.2835000021051775" rpy="-4.530171917137859e-15 -2.0539484545575828e-15 -1.5746088780480803" />
            <geometry>
                <mesh filename="meshes/Backpart.stl" scale="0.001 0.001 0.001" />
            </geometry>
        </collision>
    </link>
    <link name="Base_link">
        <inertial>
            <origin xyz="-0.18231474926451013 -0.16574314175727461 0.29280299670427995" rpy="0.0 0.0 0.0" />
            <mass value="0.0036615962412117928" />
            <inertia ixx="4.3452480168672554e-08" iyy="7.505361749267862e-08" izz="4.3452480167195746e-08" ixy="1.4998277566592202e-18" iyz="-1.097554315318403e-17" ixz="-2.99757533226139e-18" />
        </inertial>
        <visual name="Base_link_visual">
            <origin xyz="0.0 0.0 0.0" rpy="0.0 0.0 0.0" />
            <geometry>
                <mesh filename="meshes/Base_link.stl" scale="0.001 0.001 0.001" />
            </geometry>
        </visual>
        <collision name="Base_link_collision">
            <origin xyz="0.0 0.0 0.0" rpy="0.0 0.0 0.0" />
            <geometry>
                <mesh filename="meshes/Base_link.stl" scale="0.001 0.001 0.001" />
            </geometry>
        </collision>
    </link>
    <joint name="Frontpart_FL_j_hip" type="revolute">
        <origin xyz="0.13877973000000002 0.01 0.0689438" rpy="3.1415926535897927 -4.771497806585007e-35 -3.944304526105059e-31" />
        <parent link="Frontpart" />
        <child link="FL_hip" />
        <axis xyz="-0.999971 3.4020296938582826e-18 -0.007624999999996716" />
        <limit lower="-0.523599" upper="0.523599" effort="60" velocity="100" />
    </joint>
    <joint name="Frontpart_FR_j_hip" type="revolute">
        <origin xyz="0.13771223 0.01 -0.07105213" rpy="3.1415926535897927 -4.771497806585007e-35 -3.944304526105059e-31" />
        <parent link="Frontpart" />
        <child link="FR_hip" />
        <axis xyz="-0.999971 3.4020296938582826e-18 -0.007624999999996716" />
        <limit lower="-0.523599" upper="0.523599" effort="60" velocity="100" />
    </joint>
    <joint name="Backpart_RR_j_hip" type="revolute">
        <origin xyz="-0.17626560000000002 -0.06932849 -0.0175" rpy="-1.5707963267948968 7.689375450873787e-28 -3.1415926535863945" />
        <parent link="Backpart" />
        <child link="RR_hip" />
        <axis xyz="0.9999929999999873 9.234075398025226e-19 -0.0038130000033988177" />
        <limit lower="-0.523599" upper="0.523599" effort="60" velocity="100" />
    </joint>
    <joint name="Backpart_RL_j_hip" type="revolute">
        <origin xyz="-0.17573185000000002 0.0706705 -0.0175" rpy="-1.5707963267948968 7.689375450873787e-28 -3.1415926535863945" />
        <parent link="Backpart" />
        <child link="RL_hip" />
        <axis xyz="0.9999929999999873 9.234075398025226e-19 -0.0038130000033988177" />
        <limit lower="-0.523599" upper="0.523599" effort="60" velocity="100" />
    </joint>
    <joint name="FR_hip_FR_j_femur" type="revolute">
        <origin xyz="0.05810505999999993 0.0 -0.01355734000000001" rpy="1.5707963267948981 -4.461678287026247e-16 1.5707963267948966" />
        <parent link="FR_hip" />
        <child link="FR_femur" />
        <axis xyz="-1.0097126761660934e-28 0.9999710000000003 -0.007625000000001545" />
        <limit lower="-2.094395" upper="2.094395" effort="60" velocity="100" />
    </joint>
    <joint name="FL_hip_FL_j_femur" type="revolute">
        <origin xyz="0.05789157000000003 -3.552713678800501e-17 0.014441840000000004" rpy="-1.5707963267948981 -4.461678287026247e-16 1.5707963267948966" />
        <parent link="FL_hip" />
        <child link="FL_femur" />
        <axis xyz="1.0097126761660934e-28 0.9999710000000003 -0.0076249999999984585" />
        <limit lower="-2.094395" upper="2.094395" effort="60" velocity="100" />
    </joint>
    <joint name="RR_hip_RR_j_femur" type="revolute">
        <origin xyz="0.05794619999995163 0.0 -0.014221030000196953" rpy="1.5707963267914962 2.421734958835809e-16 -1.5707963267948966" />
        <parent link="RR_hip" />
        <child link="RR_femur" />
        <axis xyz="1.5777107663893505e-30 0.9999930000000002 -0.0038129999999984582" />
        <limit lower="-2.094395" upper="2.094395" effort="60" velocity="100" />
    </joint>
    <joint name="RL_hip_RL_j_femur" type="revolute">
        <origin xyz="0.0580529500000468 0.0 0.013778769999802693" rpy="-1.570796326798294 2.421734958835809e-16 -1.5707963267948966" />
        <parent link="RL_hip" />
        <child link="RL_femur" />
        <axis xyz="-1.5716949131261352e-30 0.9999930000000002 -0.0038130000000012945" />
        <limit lower="-2.094395" upper="2.094395" effort="60" velocity="100" />
    </joint>
    <joint name="FR_femur_FR_j_tibia" type="revolute">
        <origin xyz="-0.14 0.05699833999999998 -0.0004346200000000522" rpy="-3.141592653589793 1.5570263517904096e-43 1.0097419586828949e-28" />
        <parent link="FR_femur" />
        <child link="FR_tibia" />
        <axis xyz="0.0 0.999971 -0.007625000000001654" />
        <limit lower="-2.094395" upper="2.094395" effort="60" velocity="100" />
    </joint>
    <joint name="FL_femur_FL_j_tibia" type="revolute">
        <origin xyz="-0.13999999999999999 0.05699833999999998 -0.00043461999999983903" rpy="-3.141592653589793 1.5587779748584241e-43 -1.0097419586828949e-28" />
        <parent link="FL_femur" />
        <child link="FL_tibia" />
        <axis xyz="0.0 0.999971 -0.0076249999999987534" />
        <limit lower="-2.094395" upper="2.094395" effort="60" velocity="100" />
    </joint>
    <joint name="RR_femur_RR_j_tibia" type="revolute">
        <origin xyz="-0.13999999999999999 0.056999589999999996 -0.00021731999999992978" rpy="-3.141592653589793 1.5777218104420233e-30 2.45227231256843e-45" />
        <parent link="RR_femur" />
        <child link="RR_tibia" />
        <axis xyz="-1.583726619652566e-30 0.9999930000000002 -0.003812999999998755" />
        <limit lower="-2.094395" upper="2.094395" effort="60" velocity="100" />
    </joint>
    <joint name="RL_femur_RL_j_tibia" type="revolute">
        <origin xyz="-0.14 0.05699957999999998 -0.0002173100000000261" rpy="-3.141592653589793 -3.1554436208840465e-30 4.203895392974451e-45" />
        <parent link="RL_femur" />
        <child link="RL_tibia" />
        <axis xyz="1.583726619652566e-30 0.9999930000000002 -0.0038130000000014055" />
        <limit lower="-2.094395" upper="2.094395" effort="60" velocity="100" />
    </joint>
    <joint name="Base_link_Back_j_Base" type="revolute">
        <origin xyz="-0.18231475134396463 -0.165743138473793 0.29980299880961664" rpy="1.6528634893082283e-15 -5.094888957201467e-15 1.5746088781181597" />
        <parent link="Base_link" />
        <child link="Backpart" />
        <axis xyz="0.0 1.5706152165479998e-17 1.0" />
        <limit lower="-0.523599" upper="0.523599" effort="60" velocity="100" />
    </joint>
    <joint name="Base_link_Spine_j_Base" type="revolute">
        <origin xyz="-0.1753147504612079 -0.1657431406758344 0.29280299880961663" rpy="-1.5669837754716363 -1.5707963267948852 0" />
        <parent link="Base_link" />
        <child link="Spine" />
        <axis xyz="1.5777107663893505e-30 0.999993 -0.003813" />
        <limit lower="-0.523599" upper="0.523599" effort="60" velocity="100" />
    </joint>
    <joint name="Spine_Front_j_Spine" type="revolute">
        <origin xyz="0.0 -0.006633950000000004 0.04802529" rpy="1.5707963267948966 -1.5707963267948966 0" />
        <parent link="Spine" />
        <child link="Frontpart" />
        <axis xyz="0.999971 2.3476043000052282e-30 -0.007625" />
        <limit lower="-0.523599" upper="0.523599" effort="60" velocity="100" />
    </joint>
</robot>