<?xml version='1.0' encoding='utf-8'?>
<robot name="(未保存)">
    <link name="SPINE_BASE">
        <inertial>
            <origin xyz="4.730573431462346e-05 0.03908216439133213 0.01994047201956025" rpy="0.0 -0.0 0.0" />
            <mass value="0.34710385517309217" />
            <inertia ixx="0.0006332253778059058" iyy="0.0006484329708629913" izz="0.0011852763281626905" ixy="-1.3656210408499249e-08" iyz="2.5299812498149253e-06" ixz="2.166879763171175e-07" />
        </inertial>
        <visual name="SPINE_BASE_visual">
            <origin xyz="-5.486041816952956e-20 -0.2765 0.04799999999999988" rpy="-1.5707963267948961 -0.0 0.0" />
            <geometry>
                <mesh filename="meshes/SPINE_BASE.stl" scale="0.001 0.001 0.001" />
            </geometry>
        </visual>
        <collision name="SPINE_BASE_collision">
            <origin xyz="-5.486041816952956e-20 -0.2765 0.04799999999999988" rpy="-1.5707963267948961 -0.0 0.0" />
            <geometry>
                <mesh filename="meshes/SPINE_BASE.stl" scale="0.001 0.001 0.001" />
            </geometry>
        </collision>
    </link>
    <link name="FR_tibia">
        <inertial>
            <origin xyz="-0.05148378769342775 2.5932378772353104e-07 -0.017000000000018556" rpy="0.0 -0.0 0.0" />
            <mass value="0.06643041309117052" />
            <inertia ixx="7.324185496567284e-06" iyy="0.00016950454321351953" izz="0.0001728263651286045" ixy="1.4322288841017716e-09" iyz="-1.441642879720985e-09" ixz="-8.792742128985563e-17" />
        </inertial>
        <visual name="FR_tibia_visual">
            <origin xyz="-0.12650000000000003 -0.24574999999999983 0.11300000000000042" rpy="-0.0 1.570796326794895 0" />
            <geometry>
                <mesh filename="meshes/FR_tibia.stl" scale="0.001 0.001 0.001" />
            </geometry>
        </visual>
        <collision name="FR_tibia_collision">
            <origin xyz="-0.12650000000000003 -0.24574999999999983 0.11300000000000042" rpy="-0.0 1.570796326794895 0" />
            <geometry>
                <mesh filename="meshes/FR_tibia.stl" scale="0.001 0.001 0.001" />
            </geometry>
        </collision>
    </link>
    <link name="FR_femur">
        <inertial>
            <origin xyz="-0.00963202800409679 0.0006632383602619641 0.04662713603913983" rpy="0.0 -0.0 0.0" />
            <mass value="0.5478239660925192" />
            <inertia ixx="0.0003898366256969016" iyy="0.0009504072991228102" izz="0.0009199706228392168" ixy="-3.5134262888756578e-06" iyz="1.036900632390802e-05" ixz="0.00012716627840619882" />
        </inertial>
        <visual name="FR_femur_visual">
            <origin xyz="-0.2665 0.24574999999999994 -0.05600000000000038" rpy="-3.141592653589793 -1.570796326794895 0" />
            <geometry>
                <mesh filename="meshes/FR_femur.stl" scale="0.001 0.001 0.001" />
            </geometry>
        </visual>
        <collision name="FR_femur_collision">
            <origin xyz="-0.2665 0.24574999999999994 -0.05600000000000038" rpy="-3.141592653589793 -1.570796326794895 0" />
            <geometry>
                <mesh filename="meshes/FR_femur.stl" scale="0.001 0.001 0.001" />
            </geometry>
        </collision>
    </link>
    <link name="FR_hip">
        <inertial>
            <origin xyz="-0.028721990193184128 -6.812056460120175e-05 -0.05130925813857452" rpy="0.0 -0.0 0.0" />
            <mass value="0.4276561259852312" />
            <inertia ixx="0.00038198130003343905" iyy="0.00030620690583912924" izz="0.0002242595560856023" ixy="-5.605003454266813e-07" iyz="-2.0866111600719207e-07" ixz="-2.563962877754782e-05" />
        </inertial>
        <visual name="FR_hip_visual">
            <origin xyz="-0.06999999999999938 -0.26650000000000007 0.1877499999999999" rpy="-1.5707963267948961 -0.0 0.0" />
            <geometry>
                <mesh filename="meshes/FR_hip.stl" scale="0.001 0.001 0.001" />
            </geometry>
        </visual>
        <collision name="FR_hip_collision">
            <origin xyz="-0.06999999999999938 -0.26650000000000007 0.1877499999999999" rpy="-1.5707963267948961 -0.0 0.0" />
            <geometry>
                <mesh filename="meshes/FR_hip.stl" scale="0.001 0.001 0.001" />
            </geometry>
        </collision>
    </link>
    <link name="FL_tibia">
        <inertial>
            <origin xyz="-0.05148378769729591 2.5932942069317735e-07 -0.01700000000001859" rpy="0.0 -0.0 0.0" />
            <mass value="0.06643041309117047" />
            <inertia ixx="7.324185496609785e-06" iyy="0.00016950454321351975" izz="0.00017282636512864612" ixy="1.4322288392158017e-09" iyz="-1.4416428805979809e-09" ixz="-8.73871228090675e-17" />
        </inertial>
        <visual name="FL_tibia_visual">
            <origin xyz="-0.1265 0.24574999999999986 0.11300000000000031" rpy="-3.141592653589793 -1.5707963267948954 0" />
            <geometry>
                <mesh filename="meshes/FL_tibia.stl" scale="0.001 0.001 0.001" />
            </geometry>
        </visual>
        <collision name="FL_tibia_collision">
            <origin xyz="-0.1265 0.24574999999999986 0.11300000000000031" rpy="-3.141592653589793 -1.5707963267948954 0" />
            <geometry>
                <mesh filename="meshes/FL_tibia.stl" scale="0.001 0.001 0.001" />
            </geometry>
        </collision>
    </link>
    <link name="FL_femur">
        <inertial>
            <origin xyz="-0.009525671367781463 -0.000663238360265268 0.04662713603913983" rpy="0.0 -0.0 0.0" />
            <mass value="0.54782396609252" />
            <inertia ixx="0.0003898366256941052" iyy="0.0009515235170791322" izz="0.0009210868407927564" ixy="3.447302694539546e-06" iyz="-1.0369006323855978e-05" ixz="0.00012862808425901168" />
        </inertial>
        <visual name="FL_femur_visual">
            <origin xyz="-0.2665 -0.24574999999999994 -0.05600000000000038" rpy="-0.0 1.570796326794895 0" />
            <geometry>
                <mesh filename="meshes/FL_femur.stl" scale="0.001 0.001 0.001" />
            </geometry>
        </visual>
        <collision name="FL_femur_collision">
            <origin xyz="-0.2665 -0.24574999999999994 -0.05600000000000038" rpy="-0.0 1.570796326794895 0" />
            <geometry>
                <mesh filename="meshes/FL_femur.stl" scale="0.001 0.001 0.001" />
            </geometry>
        </collision>
    </link>
    <link name="FL_hip">
        <inertial>
            <origin xyz="0.028721990193183763 6.812124525318097e-05 -0.05130925813857459" rpy="0.0 -0.0 0.0" />
            <mass value="0.4276561259852311" />
            <inertia ixx="0.0003819813000275618" iyy="0.00030620690583911536" izz="0.0002242595560797386" ixy="-5.60502122213755e-07" iyz="2.0865082585312344e-07" ixz="2.5639628777543578e-05" />
        </inertial>
        <visual name="FL_hip_visual">
            <origin xyz="0.07000000000000062 -0.26650000000000007 0.1877499999999999" rpy="-1.5707963267948961 -0.0 0.0" />
            <geometry>
                <mesh filename="meshes/FL_hip.stl" scale="0.001 0.001 0.001" />
            </geometry>
        </visual>
        <collision name="FL_hip_collision">
            <origin xyz="0.07000000000000062 -0.26650000000000007 0.1877499999999999" rpy="-1.5707963267948961 -0.0 0.0" />
            <geometry>
                <mesh filename="meshes/FL_hip.stl" scale="0.001 0.001 0.001" />
            </geometry>
        </collision>
    </link>
    <link name="RR_tibia">
        <inertial>
            <origin xyz="-0.051483787277296085 2.593294185615491e-07 -0.0170000003100186" rpy="0.0 -0.0 0.0" />
            <mass value="0.06643041309117047" />
            <inertia ixx="7.324185496569019e-06" iyy="0.00016950454321351953" izz="0.0001728263651286045" ixy="1.432228884318612e-09" iyz="-1.4416428801643e-09" ixz="-8.782080367806165e-17" />
        </inertial>
        <visual name="RR_tibia_visual">
            <origin xyz="-0.126 0.23399999999999985 0.1130000000000003" rpy="-0.0 1.5707963267948954 0" />
            <geometry>
                <mesh filename="meshes/RR_tibia.stl" scale="0.001 0.001 0.001" />
            </geometry>
        </visual>
        <collision name="RR_tibia_collision">
            <origin xyz="-0.126 0.23399999999999985 0.1130000000000003" rpy="-0.0 1.5707963267948954 0" />
            <geometry>
                <mesh filename="meshes/RR_tibia.stl" scale="0.001 0.001 0.001" />
            </geometry>
        </collision>
    </link>
    <link name="RR_femur">
        <inertial>
            <origin xyz="-0.009525670947856248 -0.000663238362088272 0.0466271363491398" rpy="0.0 -0.0 0.0" />
            <mass value="0.5478239660925199" />
            <inertia ixx="0.0003898366261748873" iyy="0.0009515235171001224" izz="0.0009210868412945078" ixy="3.4473024272602916e-06" iyz="-1.0369006426390278e-05" ixz="0.00012862808425460027" />
        </inertial>
        <visual name="RR_femur_visual">
            <origin xyz="-0.266 -0.23399999999999993 -0.05600000000000036" rpy="-3.141592653589793 -1.570796326794895 0" />
            <geometry>
                <mesh filename="meshes/RR_femur.stl" scale="0.001 0.001 0.001" />
            </geometry>
        </visual>
        <collision name="RR_femur_collision">
            <origin xyz="-0.266 -0.23399999999999993 -0.05600000000000036" rpy="-3.141592653589793 -1.570796326794895 0" />
            <geometry>
                <mesh filename="meshes/RR_femur.stl" scale="0.001 0.001 0.001" />
            </geometry>
        </collision>
    </link>
    <link name="RR_hip">
        <inertial>
            <origin xyz="0.02872199057616685 -6.81212493153538e-05 0.05130925875186975" rpy="0.0 -1.993352133686596e-43 0.0" />
            <mass value="0.42765614096569765" />
            <inertia ixx="0.0003819813177834133" iyy="0.0003062069227042566" izz="0.00022425957082716162" ixy="5.604986032689073e-07" iyz="2.0864847461046994e-07" ixz="-2.5639633945872447e-05" />
        </inertial>
        <visual name="RR_hip_visual">
            <origin xyz="0.0699999999994018 0.26600000000000007 -0.17600000000023788" rpy="-1.5707963267948968 -3.3988406459263266e-12 3.141592653589793" />
            <geometry>
                <mesh filename="meshes/RR_hip.stl" scale="0.001 0.001 0.001" />
            </geometry>
        </visual>
        <collision name="RR_hip_collision">
            <origin xyz="0.0699999999994018 0.26600000000000007 -0.17600000000023788" rpy="-1.5707963267948968 -3.3988406459263266e-12 3.141592653589793" />
            <geometry>
                <mesh filename="meshes/RR_hip.stl" scale="0.001 0.001 0.001" />
            </geometry>
        </collision>
    </link>
    <link name="RL_tibia">
        <inertial>
            <origin xyz="-0.051483789273427866 2.5932378978410497e-07 -0.016999999690018603" rpy="0.0 -0.0 0.0" />
            <mass value="0.06643041309117051" />
            <inertia ixx="7.32418549660805e-06" iyy="0.0001695045432135191" izz="0.0001728263651286444" ixy="1.4322288387821208e-09" iyz="-1.441642879288134e-09" ixz="-8.738531984584179e-17" />
        </inertial>
        <visual name="RL_tibia_visual">
            <origin xyz="-0.12600000000000003 -0.23399999999999985 0.11300000000000032" rpy="-3.141592653589793 -1.5707963267948952 0" />
            <geometry>
                <mesh filename="meshes/RL_tibia.stl" scale="0.001 0.001 0.001" />
            </geometry>
        </visual>
        <collision name="RL_tibia_collision">
            <origin xyz="-0.12600000000000003 -0.23399999999999985 0.11300000000000032" rpy="-3.141592653589793 -1.5707963267948952 0" />
            <geometry>
                <mesh filename="meshes/RL_tibia.stl" scale="0.001 0.001 0.001" />
            </geometry>
        </collision>
    </link>
    <link name="RL_femur">
        <inertial>
            <origin xyz="-0.009632029584177247 0.000663238362084968 0.04662713572913987" rpy="0.0 -0.0 0.0" />
            <mass value="0.5478239660925199" />
            <inertia ixx="0.00038983662617207704" iyy="0.0009504072991454657" izz="0.0009199706233370408" ixy="-3.513426021672763e-06" iyz="1.0369006426445798e-05" ixz="0.0001271662784018863" />
        </inertial>
        <visual name="RL_femur_visual">
            <origin xyz="-0.266 0.23399999999999993 -0.0560000000000003" rpy="-0.0 1.5707963267948952 0" />
            <geometry>
                <mesh filename="meshes/RL_femur.stl" scale="0.001 0.001 0.001" />
            </geometry>
        </visual>
        <collision name="RL_femur_collision">
            <origin xyz="-0.266 0.23399999999999993 -0.0560000000000003" rpy="-0.0 1.5707963267948952 0" />
            <geometry>
                <mesh filename="meshes/RL_femur.stl" scale="0.001 0.001 0.001" />
            </geometry>
        </collision>
    </link>
    <link name="RL_hip">
        <inertial>
            <origin xyz="-0.02872199119581806 6.812172885240387e-05 0.051309258752064865" rpy="0.0 -1.993352133686596e-43 0.0" />
            <mass value="0.42765614096569793" />
            <inertia ixx="0.0003819813177896531" iyy="0.00030620692270427394" izz="0.00022425957083269723" ixy="5.604968298154315e-07" iyz="-2.0865824064597362e-07" ixz="2.5639633944795096e-05" />
        </inertial>
        <visual name="RL_hip_visual">
            <origin xyz="-0.0700000000005982 0.26600000000000007 -0.175999999999762" rpy="-1.5707963267948968 -3.3988406459263266e-12 3.141592653589793" />
            <geometry>
                <mesh filename="meshes/RL_hip.stl" scale="0.001 0.001 0.001" />
            </geometry>
        </visual>
        <collision name="RL_hip_collision">
            <origin xyz="-0.0700000000005982 0.26600000000000007 -0.175999999999762" rpy="-1.5707963267948968 -3.3988406459263266e-12 3.141592653589793" />
            <geometry>
                <mesh filename="meshes/RL_hip.stl" scale="0.001 0.001 0.001" />
            </geometry>
        </collision>
    </link>
    <link name="frontbase">
        <inertial>
            <origin xyz="0.00033560359531662365 0.12433305493566968 0.2883193258007625" rpy="0.0 0.0 0.0" />
            <mass value="2.6950744218640232" />
            <inertia ixx="0.010735203641671631" iyy="0.01342120187068302" izz="0.01319160203613616" ixy="1.0876131008020088e-05" iyz="-0.00048731891085616874" ixz="2.4188906997157385e-05" />
        </inertial>
        <visual name="frontbase_visual">
            <origin xyz="0.0 0.0 0.0" rpy="0.0 0.0 0.0" />
            <geometry>
                <mesh filename="meshes/frontbase.stl" scale="0.001 0.001 0.001" />
            </geometry>
        </visual>
        <collision name="frontbase_collision">
            <origin xyz="0.0 0.0 0.0" rpy="0.0 0.0 0.0" />
            <geometry>
                <mesh filename="meshes/frontbase.stl" scale="0.001 0.001 0.001" />
            </geometry>
        </collision>
    </link>
    <link name="backbase">
        <inertial>
            <origin xyz="0.000130579877546998 -0.10870630519984736 0.012666260511875329" rpy="0.0 -0.0 0.0" />
            <mass value="2.332620946077069" />
            <inertia ixx="0.009075427121205487" iyy="0.011882557935249005" izz="0.012167354508195762" ixy="2.2141403524564495e-06" iyz="-1.0456140516562673e-05" ixz="4.236205066399942e-06" />
        </inertial>
        <visual name="backbase_visual">
            <origin xyz="-7.986165859356578e-16 3.65579971799344e-17 -0.27649999999999997" rpy="1.3221698799252948e-16 2.8883059165846576e-15 0.0" />
            <geometry>
                <mesh filename="meshes/backbase.stl" scale="0.001 0.001 0.001" />
            </geometry>
        </visual>
        <collision name="backbase_collision">
            <origin xyz="-7.986165859356578e-16 3.65579971799344e-17 -0.27649999999999997" rpy="1.3221698799252948e-16 2.8883059165846576e-15 0.0" />
            <geometry>
                <mesh filename="meshes/backbase.stl" scale="0.001 0.001 0.001" />
            </geometry>
        </collision>
    </link>
    <link name="spine_R_link">
        <inertial>
            <origin xyz="-2.0792256805179932e-14 0.03999999999622904 1.2229364187987813e-11" rpy="0.0 -0.0 0.0" />
            <mass value="0.051340874420613275" />
            <inertia ixx="4.584889544408978e-05" iyy="1.2012494517181158e-06" izz="4.5208550973503073e-05" ixy="-1.9927635930283571e-16" iyz="8.347272525965899e-16" ixz="9.90960785651751e-17" />
        </inertial>
        <visual name="spine_R_link_visual">
            <origin xyz="-0.061500000000000006 0.0805 -0.3565" rpy="0.0 -0.0 0.0" />
            <geometry>
                <mesh filename="meshes/spine_R_link.stl" scale="0.001 0.001 0.001" />
            </geometry>
        </visual>
        <collision name="spine_R_link_collision">
            <origin xyz="-0.061500000000000006 0.0805 -0.3565" rpy="0.0 -0.0 0.0" />
            <geometry>
                <mesh filename="meshes/spine_R_link.stl" scale="0.001 0.001 0.001" />
            </geometry>
        </collision>
    </link>
    <link name="spine_R_bar">
        <inertial>
            <origin xyz="0.060205628365049724 -3.139977167165853e-12 -0.00659945826011354" rpy="0.0 -0.0 0.0" />
            <mass value="0.031645801946168124" />
            <inertia ixx="2.8953645025755212e-06" iyy="3.181968096638418e-05" izz="3.095234208204326e-05" ixy="1.543260735067735e-15" iyz="1.2799179420539437e-16" ixz="-3.696151061336419e-06" />
        </inertial>
        <visual name="spine_R_bar_visual">
            <origin xyz="-0.276499999999999 0.08049999999999989 0.06100000000000016" rpy="-0.0 1.5707963267948806 0" />
            <geometry>
                <mesh filename="meshes/spine_R_bar.stl" scale="0.001 0.001 0.001" />
            </geometry>
        </visual>
        <collision name="spine_R_bar_collision">
            <origin xyz="-0.276499999999999 0.08049999999999989 0.06100000000000016" rpy="-0.0 1.5707963267948806 0" />
            <geometry>
                <mesh filename="meshes/spine_R_bar.stl" scale="0.001 0.001 0.001" />
            </geometry>
        </collision>
    </link>
    <link name="spine_RL_link">
        <inertial>
            <origin xyz="-2.106759211528697e-14 0.039999999994050975 -1.2586554021254416e-12" rpy="0.0 -0.0 0.0" />
            <mass value="0.05134087442061767" />
            <inertia ixx="4.58488954440759e-05" iyy="1.2012494516955644e-06" izz="4.52085509735066e-05" ixy="1.9960161995458137e-16" iyz="-3.9258960665700116e-16" ixz="1.0126448291014611e-16" />
        </inertial>
        <visual name="spine_RL_link_visual">
            <origin xyz="0.061500000000000006 0.0805 -0.3565" rpy="0.0 -0.0 0.0" />
            <geometry>
                <mesh filename="meshes/spine_RL_link.stl" scale="0.001 0.001 0.001" />
            </geometry>
        </visual>
        <collision name="spine_RL_link_collision">
            <origin xyz="0.061500000000000006 0.0805 -0.3565" rpy="0.0 -0.0 0.0" />
            <geometry>
                <mesh filename="meshes/spine_RL_link.stl" scale="0.001 0.001 0.001" />
            </geometry>
        </collision>
    </link>
    <link name="spine_L_bar">
        <inertial>
            <origin xyz="0.06020530069433143 -0.00010413418241736138 -0.006558103121183239" rpy="0.0 -0.0 0.0" />
            <mass value="0.03164580194616816" />
            <inertia ixx="2.89296070835705e-06" iyy="3.1815550520951016e-05" izz="3.095324773523703e-05" ixy="6.522642423109066e-08" iyz="2.0621112164106902e-08" ixz="-3.721991389965154e-06" />
        </inertial>
        <visual name="spine_L_bar_visual">
            <origin xyz="-0.27650000000000036 -0.08050000000000013 0.06099999999999984" rpy="-3.141592653589793 -1.5707963267948903 0" />
            <geometry>
                <mesh filename="meshes/spine_L_bar.stl" scale="0.001 0.001 0.001" />
            </geometry>
        </visual>
        <collision name="spine_L_bar_collision">
            <origin xyz="-0.27650000000000036 -0.08050000000000013 0.06099999999999984" rpy="-3.141592653589793 -1.5707963267948903 0" />
            <geometry>
                <mesh filename="meshes/spine_L_bar.stl" scale="0.001 0.001 0.001" />
            </geometry>
        </collision>
    </link>
    <joint name="SPINE_BASE_j_universal" type="continuous">
        <origin xyz="-5.48604181695297e-20 -3.552713678800501e-17 0.048" rpy="-1.5707963267948963 -8.559431098841987e-31 2.8883059165846576e-15" />
        <parent link="SPINE_BASE" />
        <child link="backbase" />
        <axis xyz="2.8883059165846576e-15 -1.3221698799252948e-16 1.0" />
    </joint>
    <joint name="frontbase_F_j_spine" type="continuous">
        <origin xyz="0.0 0.048 0.27649999999999997" rpy="1.5707963267948961 -0.0 0.0" />
        <parent link="frontbase" />
        <child link="SPINE_BASE" />
        <axis xyz="0.0 -4.285647899927857e-16 1.0" />
    </joint>
    <joint name="backbase_RL_j_spine" type="continuous">
        <origin xyz="-0.061 -0.0805 1.7763568394002506e-16" rpy="3.1415926535897913 -1.5707963267948937 0" />
        <parent link="backbase" />
        <child link="spine_L_bar" />
        <axis xyz="0.0 -1.991835509615962e-15 1.0" />
    </joint>
    <joint name="spine_R_bar_RR_j_link" type="continuous">
        <origin xyz="0.08 0.0 -0.0005000000000000072" rpy="-0.0 1.5707963267948806 0" />
        <parent link="spine_R_bar" />
        <child link="spine_R_link" />
        <axis xyz="1.0 0.0 0.0" />
    </joint>
    <joint name="spine_L_bar_RL_j_link" type="continuous">
        <origin xyz="0.08 0.0 -0.0005000000000000072" rpy="-3.141592653589793 -1.5707963267948903 0" />
        <parent link="spine_L_bar" />
        <child link="spine_RL_link" />
        <axis xyz="1.0 0.0 0.0" />
    </joint>
    <joint name="backbase_RR_j_spine" type="continuous">
        <origin xyz="0.061 -0.0805 -1.7763568394002506e-16" rpy="-1.9920051279636517e-15 -1.5707963267948937 0" />
        <parent link="backbase" />
        <child link="spine_R_bar" />
        <axis xyz="0.0 -1.9920051279636497e-15 1.0" />
    </joint>
    <joint name="frontbase_FL_j_hip" type="continuous">
        <origin xyz="-0.07 0.18775 0.2665" rpy="1.5707963267948961 -0.0 0.0" />
        <parent link="frontbase" />
        <child link="FL_hip" />
        <axis xyz="0.0 -4.461678287026247e-16 1.0" />
    </joint>
    <joint name="frontbase_FR__j_hip" type="continuous">
        <origin xyz="0.07 0.18775 0.2665" rpy="1.5707963267948961 -0.0 0.0" />
        <parent link="frontbase" />
        <child link="FR_hip" />
        <axis xyz="0.0 -4.461678287026247e-16 1.0" />
    </joint>
    <joint name="backbase_RR_j_hip" type="continuous">
        <origin xyz="0.06999999999999998 -0.17600000000000002 -0.010500000000000185" rpy="-1.570796326794897 -2.888305916583385e-15 -3.1415926535863945" />
        <parent link="backbase" />
        <child link="RR_hip" />
        <axis xyz="3.3988406459263266e-12 -2.421734958835825e-16 1.0" />
    </joint>
    <joint name="backbase_RL_j_hip" type="continuous">
        <origin xyz="-0.07000000000000003 -0.17600000000000002 -0.010499999999999794" rpy="-1.570796326794897 -2.888305916583385e-15 -3.1415926535863945" />
        <parent link="backbase" />
        <child link="RL_hip" />
        <axis xyz="3.3988406459263266e-12 -2.421734958835825e-16 1.0" />
    </joint>
    <joint name="FR_hip_FR_j_femur" type="continuous">
        <origin xyz="-0.0140000000000002 3.552713678800501e-17 -0.05800000000000001" rpy="1.5707963267948981 -4.461678287026247e-16 1.5707963267948966" />
        <parent link="FR_hip" />
        <child link="FR_femur" />
        <axis xyz="0.0 1.542871572214893e-15 1.0" />
    </joint>
    <joint name="FL_hip_FL_j_femur" type="continuous">
        <origin xyz="0.013999999999999808 3.552713678800501e-17 -0.05800000000000001" rpy="-1.5707963267948981 -4.461678287026247e-16 1.5707963267948966" />
        <parent link="FL_hip" />
        <child link="FL_femur" />
        <axis xyz="0.0 -1.542871572214893e-15 1.0" />
    </joint>
    <joint name="RR_hip_RR_j_femur" type="continuous">
        <origin xyz="0.014000000000197134 -3.552713678800501e-17 0.05799999999995237" rpy="1.5707963267914962 2.421734958835825e-16 -1.5707963267948966" />
        <parent link="RR_hip" />
        <child link="RR_femur" />
        <axis xyz="0.0 -1.542871572214893e-15 1.0" />
    </joint>
    <joint name="RL_hip_RL_j_femur" type="continuous">
        <origin xyz="-0.013999999999802873 -3.552713678800501e-17 0.058000000000047576" rpy="-1.570796326798294 2.421734958835825e-16 -1.5707963267948966" />
        <parent link="RL_hip" />
        <child link="RL_femur" />
        <axis xyz="-0.0 1.2930713916742327e-15 1.0" />
    </joint>
    <joint name="FR_femur_FR_j_tibia" type="continuous">
        <origin xyz="-0.13999999999999996 1.0658141036401502e-16 0.057" rpy="-3.141592653589793 -0.0 0.0" />
        <parent link="FR_femur" />
        <child link="FR_tibia" />
        <axis xyz="0.0 1.6538938746774084e-15 1.0" />
    </joint>
    <joint name="FL_femur_FL_j_tibia" type="continuous">
        <origin xyz="-0.13999999999999999 -1.0658141036401502e-16 0.057" rpy="-3.141592653589793 -0.0 0.0" />
        <parent link="FL_femur" />
        <child link="FL_tibia" />
        <axis xyz="0.0 -1.246280556996444e-15 1.0" />
    </joint>
    <joint name="RR_femur_RR_j_tibia" type="continuous">
        <origin xyz="-0.14 -1.0658141036401502e-16 0.057" rpy="-3.141592653589793 -0.0 0.0" />
        <parent link="RR_femur" />
        <child link="RR_tibia" />
        <axis xyz="0.0 -1.246280556996444e-15 1.0" />
    </joint>
    <joint name="RL_femur_RL_j_tibia" type="continuous">
        <origin xyz="-0.14 7.105427357601002e-17 0.05700000000000001" rpy="-3.141592653589793 -0.0 0.0" />
        <parent link="RL_femur" />
        <child link="RL_tibia" />
        <axis xyz="0.0 1.4040936941367484e-15 1.0" />
    </joint>
    <joint name="SPINE_BASE_旋转-29" type="continuous">
        <origin xyz="0.061500000000000006 0.07999999999999996 0.048500000000000036" rpy="-1.5707963267948961 -0.0 0.0" />
        <parent link="SPINE_BASE" />
        <child link="spine_R_link" />
        <axis xyz="1.0 0.0 0.0" />
    </joint>
    <joint name="SPINE_BASE_旋转-30" type="continuous">
        <origin xyz="-0.061500000000000006 0.07999999999999996 0.048500000000000036" rpy="-1.5707963267948961 -0.0 0.0" />
        <parent link="SPINE_BASE" />
        <child link="spine_RL_link" />
        <axis xyz="1.0 0.0 0.0" />
    </joint>
</robot>